[2025-08-21 16:07:08,595] ERROR in main: Unhandled error: 404 Not Found: The requested URL was not found on the server. If you entered the URL manually please check your spelling and try again.
Traceback (most recent call last):
  File "C:\Users\Aseman\AppData\Local\Packages\PythonSoftwareFoundation.Python.3.10_qbz5n2kfra8p0\LocalCache\local-packages\Python310\site-packages\flask\app.py", line 1484, in full_dispatch_request
    rv = self.dispatch_request()
  File "C:\Users\Aseman\AppData\Local\Packages\PythonSoftwareFoundation.Python.3.10_qbz5n2kfra8p0\LocalCache\local-packages\Python310\site-packages\flask\app.py", line 1469, in dispatch_request
    return self.ensure_sync(self.view_functions[rule.endpoint])(**view_args)
  File "C:\Users\Aseman\AppData\Local\Packages\PythonSoftwareFoundation.Python.3.10_qbz5n2kfra8p0\LocalCache\local-packages\Python310\site-packages\flask\app.py", line 502, in <lambda>
    view_func=lambda **kw: self_ref().send_static_file(**kw),  # type: ignore # noqa: B950
  File "C:\Users\Aseman\AppData\Local\Packages\PythonSoftwareFoundation.Python.3.10_qbz5n2kfra8p0\LocalCache\local-packages\Python310\site-packages\flask\scaffold.py", line 317, in send_static_file
    return send_from_directory(
  File "C:\Users\Aseman\AppData\Local\Packages\PythonSoftwareFoundation.Python.3.10_qbz5n2kfra8p0\LocalCache\local-packages\Python310\site-packages\flask\helpers.py", line 557, in send_from_directory
    return werkzeug.utils.send_from_directory(  # type: ignore[return-value]
  File "C:\Users\Aseman\AppData\Local\Packages\PythonSoftwareFoundation.Python.3.10_qbz5n2kfra8p0\LocalCache\local-packages\Python310\site-packages\werkzeug\utils.py", line 574, in send_from_directory
    raise NotFound()
werkzeug.exceptions.NotFound: 404 Not Found: The requested URL was not found on the server. If you entered the URL manually please check your spelling and try again.
[2025-08-21 16:07:10,938] ERROR in main: Unhandled error: 404 Not Found: The requested URL was not found on the server. If you entered the URL manually please check your spelling and try again.
Traceback (most recent call last):
  File "C:\Users\Aseman\AppData\Local\Packages\PythonSoftwareFoundation.Python.3.10_qbz5n2kfra8p0\LocalCache\local-packages\Python310\site-packages\flask\app.py", line 1484, in full_dispatch_request
    rv = self.dispatch_request()
  File "C:\Users\Aseman\AppData\Local\Packages\PythonSoftwareFoundation.Python.3.10_qbz5n2kfra8p0\LocalCache\local-packages\Python310\site-packages\flask\app.py", line 1458, in dispatch_request
    self.raise_routing_exception(req)
  File "C:\Users\Aseman\AppData\Local\Packages\PythonSoftwareFoundation.Python.3.10_qbz5n2kfra8p0\LocalCache\local-packages\Python310\site-packages\flask\app.py", line 1440, in raise_routing_exception
    raise request.routing_exception  # type: ignore
  File "C:\Users\Aseman\AppData\Local\Packages\PythonSoftwareFoundation.Python.3.10_qbz5n2kfra8p0\LocalCache\local-packages\Python310\site-packages\flask\ctx.py", line 353, in match_request
    result = self.url_adapter.match(return_rule=True)  # type: ignore
  File "C:\Users\Aseman\AppData\Local\Packages\PythonSoftwareFoundation.Python.3.10_qbz5n2kfra8p0\LocalCache\local-packages\Python310\site-packages\werkzeug\routing\map.py", line 655, in match
    raise NotFound() from None
werkzeug.exceptions.NotFound: 404 Not Found: The requested URL was not found on the server. If you entered the URL manually please check your spelling and try again.
[2025-08-21 16:07:14,330] ERROR in main: Unhandled error: 404 Not Found: The requested URL was not found on the server. If you entered the URL manually please check your spelling and try again.
Traceback (most recent call last):
  File "C:\Users\Aseman\AppData\Local\Packages\PythonSoftwareFoundation.Python.3.10_qbz5n2kfra8p0\LocalCache\local-packages\Python310\site-packages\flask\app.py", line 1484, in full_dispatch_request
    rv = self.dispatch_request()
  File "C:\Users\Aseman\AppData\Local\Packages\PythonSoftwareFoundation.Python.3.10_qbz5n2kfra8p0\LocalCache\local-packages\Python310\site-packages\flask\app.py", line 1458, in dispatch_request
    self.raise_routing_exception(req)
  File "C:\Users\Aseman\AppData\Local\Packages\PythonSoftwareFoundation.Python.3.10_qbz5n2kfra8p0\LocalCache\local-packages\Python310\site-packages\flask\app.py", line 1440, in raise_routing_exception
    raise request.routing_exception  # type: ignore
  File "C:\Users\Aseman\AppData\Local\Packages\PythonSoftwareFoundation.Python.3.10_qbz5n2kfra8p0\LocalCache\local-packages\Python310\site-packages\flask\ctx.py", line 353, in match_request
    result = self.url_adapter.match(return_rule=True)  # type: ignore
  File "C:\Users\Aseman\AppData\Local\Packages\PythonSoftwareFoundation.Python.3.10_qbz5n2kfra8p0\LocalCache\local-packages\Python310\site-packages\werkzeug\routing\map.py", line 655, in match
    raise NotFound() from None
werkzeug.exceptions.NotFound: 404 Not Found: The requested URL was not found on the server. If you entered the URL manually please check your spelling and try again.
[2025-08-21 16:07:27,135] ERROR in main: Unhandled error: 404 Not Found: The requested URL was not found on the server. If you entered the URL manually please check your spelling and try again.
Traceback (most recent call last):
  File "C:\Users\Aseman\AppData\Local\Packages\PythonSoftwareFoundation.Python.3.10_qbz5n2kfra8p0\LocalCache\local-packages\Python310\site-packages\flask\app.py", line 1484, in full_dispatch_request
    rv = self.dispatch_request()
  File "C:\Users\Aseman\AppData\Local\Packages\PythonSoftwareFoundation.Python.3.10_qbz5n2kfra8p0\LocalCache\local-packages\Python310\site-packages\flask\app.py", line 1469, in dispatch_request
    return self.ensure_sync(self.view_functions[rule.endpoint])(**view_args)
  File "C:\Users\Aseman\AppData\Local\Packages\PythonSoftwareFoundation.Python.3.10_qbz5n2kfra8p0\LocalCache\local-packages\Python310\site-packages\flask\app.py", line 502, in <lambda>
    view_func=lambda **kw: self_ref().send_static_file(**kw),  # type: ignore # noqa: B950
  File "C:\Users\Aseman\AppData\Local\Packages\PythonSoftwareFoundation.Python.3.10_qbz5n2kfra8p0\LocalCache\local-packages\Python310\site-packages\flask\scaffold.py", line 317, in send_static_file
    return send_from_directory(
  File "C:\Users\Aseman\AppData\Local\Packages\PythonSoftwareFoundation.Python.3.10_qbz5n2kfra8p0\LocalCache\local-packages\Python310\site-packages\flask\helpers.py", line 557, in send_from_directory
    return werkzeug.utils.send_from_directory(  # type: ignore[return-value]
  File "C:\Users\Aseman\AppData\Local\Packages\PythonSoftwareFoundation.Python.3.10_qbz5n2kfra8p0\LocalCache\local-packages\Python310\site-packages\werkzeug\utils.py", line 574, in send_from_directory
    raise NotFound()
werkzeug.exceptions.NotFound: 404 Not Found: The requested URL was not found on the server. If you entered the URL manually please check your spelling and try again.
[2025-08-21 16:08:01,672] ERROR in main: Unhandled error: 404 Not Found: The requested URL was not found on the server. If you entered the URL manually please check your spelling and try again.
Traceback (most recent call last):
  File "C:\Users\Aseman\AppData\Local\Packages\PythonSoftwareFoundation.Python.3.10_qbz5n2kfra8p0\LocalCache\local-packages\Python310\site-packages\flask\app.py", line 1484, in full_dispatch_request
    rv = self.dispatch_request()
  File "C:\Users\Aseman\AppData\Local\Packages\PythonSoftwareFoundation.Python.3.10_qbz5n2kfra8p0\LocalCache\local-packages\Python310\site-packages\flask\app.py", line 1469, in dispatch_request
    return self.ensure_sync(self.view_functions[rule.endpoint])(**view_args)
  File "C:\Users\Aseman\AppData\Local\Packages\PythonSoftwareFoundation.Python.3.10_qbz5n2kfra8p0\LocalCache\local-packages\Python310\site-packages\flask\app.py", line 502, in <lambda>
    view_func=lambda **kw: self_ref().send_static_file(**kw),  # type: ignore # noqa: B950
  File "C:\Users\Aseman\AppData\Local\Packages\PythonSoftwareFoundation.Python.3.10_qbz5n2kfra8p0\LocalCache\local-packages\Python310\site-packages\flask\scaffold.py", line 317, in send_static_file
    return send_from_directory(
  File "C:\Users\Aseman\AppData\Local\Packages\PythonSoftwareFoundation.Python.3.10_qbz5n2kfra8p0\LocalCache\local-packages\Python310\site-packages\flask\helpers.py", line 557, in send_from_directory
    return werkzeug.utils.send_from_directory(  # type: ignore[return-value]
  File "C:\Users\Aseman\AppData\Local\Packages\PythonSoftwareFoundation.Python.3.10_qbz5n2kfra8p0\LocalCache\local-packages\Python310\site-packages\werkzeug\utils.py", line 574, in send_from_directory
    raise NotFound()
werkzeug.exceptions.NotFound: 404 Not Found: The requested URL was not found on the server. If you entered the URL manually please check your spelling and try again.
[2025-08-21 16:08:03,482] ERROR in main: Unhandled error: 'str object' has no attribute 'strftime'
Traceback (most recent call last):
  File "C:\Users\Aseman\AppData\Local\Packages\PythonSoftwareFoundation.Python.3.10_qbz5n2kfra8p0\LocalCache\local-packages\Python310\site-packages\flask\app.py", line 1484, in full_dispatch_request
    rv = self.dispatch_request()
  File "C:\Users\Aseman\AppData\Local\Packages\PythonSoftwareFoundation.Python.3.10_qbz5n2kfra8p0\LocalCache\local-packages\Python310\site-packages\flask\app.py", line 1469, in dispatch_request
    return self.ensure_sync(self.view_functions[rule.endpoint])(**view_args)
  File "C:\Users\Aseman\OneDrive\Desktop\py-code\G\app\routes\main.py", line 469, in my_lands
    return render_template('my_lands.html',
  File "C:\Users\Aseman\AppData\Local\Packages\PythonSoftwareFoundation.Python.3.10_qbz5n2kfra8p0\LocalCache\local-packages\Python310\site-packages\flask\templating.py", line 151, in render_template
    return _render(app, template, context)
  File "C:\Users\Aseman\AppData\Local\Packages\PythonSoftwareFoundation.Python.3.10_qbz5n2kfra8p0\LocalCache\local-packages\Python310\site-packages\flask\templating.py", line 132, in _render
    rv = template.render(context)
  File "C:\Users\Aseman\AppData\Local\Packages\PythonSoftwareFoundation.Python.3.10_qbz5n2kfra8p0\LocalCache\local-packages\Python310\site-packages\jinja2\environment.py", line 1301, in render
    self.environment.handle_exception()
  File "C:\Users\Aseman\AppData\Local\Packages\PythonSoftwareFoundation.Python.3.10_qbz5n2kfra8p0\LocalCache\local-packages\Python310\site-packages\jinja2\environment.py", line 936, in handle_exception
    raise rewrite_traceback_stack(source=source)
  File "C:\Users\Aseman\OneDrive\Desktop\py-code\G\app\templates\my_lands.html", line 1, in top-level template code
    {% extends "base.html" %}
  File "C:\Users\Aseman\OneDrive\Desktop\py-code\G\app\templates\base.html", line 100, in top-level template code
    {% block content %}{% endblock %}
  File "C:\Users\Aseman\OneDrive\Desktop\py-code\G\app\templates\my_lands.html", line 148, in block 'content'
    {{ land.created_at.strftime('%Y/%m/%d') }}
  File "C:\Users\Aseman\AppData\Local\Packages\PythonSoftwareFoundation.Python.3.10_qbz5n2kfra8p0\LocalCache\local-packages\Python310\site-packages\jinja2\utils.py", line 83, in from_obj
    if hasattr(obj, "jinja_pass_arg"):
jinja2.exceptions.UndefinedError: 'str object' has no attribute 'strftime'
[2025-08-21 16:08:03,640] ERROR in main: Unhandled error: 404 Not Found: The requested URL was not found on the server. If you entered the URL manually please check your spelling and try again.
Traceback (most recent call last):
  File "C:\Users\Aseman\AppData\Local\Packages\PythonSoftwareFoundation.Python.3.10_qbz5n2kfra8p0\LocalCache\local-packages\Python310\site-packages\flask\app.py", line 1484, in full_dispatch_request
    rv = self.dispatch_request()
  File "C:\Users\Aseman\AppData\Local\Packages\PythonSoftwareFoundation.Python.3.10_qbz5n2kfra8p0\LocalCache\local-packages\Python310\site-packages\flask\app.py", line 1458, in dispatch_request
    self.raise_routing_exception(req)
  File "C:\Users\Aseman\AppData\Local\Packages\PythonSoftwareFoundation.Python.3.10_qbz5n2kfra8p0\LocalCache\local-packages\Python310\site-packages\flask\app.py", line 1440, in raise_routing_exception
    raise request.routing_exception  # type: ignore
  File "C:\Users\Aseman\AppData\Local\Packages\PythonSoftwareFoundation.Python.3.10_qbz5n2kfra8p0\LocalCache\local-packages\Python310\site-packages\flask\ctx.py", line 353, in match_request
    result = self.url_adapter.match(return_rule=True)  # type: ignore
  File "C:\Users\Aseman\AppData\Local\Packages\PythonSoftwareFoundation.Python.3.10_qbz5n2kfra8p0\LocalCache\local-packages\Python310\site-packages\werkzeug\routing\map.py", line 655, in match
    raise NotFound() from None
werkzeug.exceptions.NotFound: 404 Not Found: The requested URL was not found on the server. If you entered the URL manually please check your spelling and try again.
[2025-08-21 16:13:20,131] ERROR in main: Unhandled error: 'str object' has no attribute 'strftime'
Traceback (most recent call last):
  File "C:\Users\Aseman\AppData\Local\Packages\PythonSoftwareFoundation.Python.3.10_qbz5n2kfra8p0\LocalCache\local-packages\Python310\site-packages\flask\app.py", line 1484, in full_dispatch_request
    rv = self.dispatch_request()
  File "C:\Users\Aseman\AppData\Local\Packages\PythonSoftwareFoundation.Python.3.10_qbz5n2kfra8p0\LocalCache\local-packages\Python310\site-packages\flask\app.py", line 1469, in dispatch_request
    return self.ensure_sync(self.view_functions[rule.endpoint])(**view_args)
  File "C:\Users\Aseman\OneDrive\Desktop\py-code\G\app\routes\main.py", line 469, in my_lands
    return render_template('my_lands.html',
  File "C:\Users\Aseman\AppData\Local\Packages\PythonSoftwareFoundation.Python.3.10_qbz5n2kfra8p0\LocalCache\local-packages\Python310\site-packages\flask\templating.py", line 151, in render_template
    return _render(app, template, context)
  File "C:\Users\Aseman\AppData\Local\Packages\PythonSoftwareFoundation.Python.3.10_qbz5n2kfra8p0\LocalCache\local-packages\Python310\site-packages\flask\templating.py", line 132, in _render
    rv = template.render(context)
  File "C:\Users\Aseman\AppData\Local\Packages\PythonSoftwareFoundation.Python.3.10_qbz5n2kfra8p0\LocalCache\local-packages\Python310\site-packages\jinja2\environment.py", line 1301, in render
    self.environment.handle_exception()
  File "C:\Users\Aseman\AppData\Local\Packages\PythonSoftwareFoundation.Python.3.10_qbz5n2kfra8p0\LocalCache\local-packages\Python310\site-packages\jinja2\environment.py", line 936, in handle_exception
    raise rewrite_traceback_stack(source=source)
  File "C:\Users\Aseman\OneDrive\Desktop\py-code\G\app\templates\my_lands.html", line 1, in top-level template code
    {% extends "base.html" %}
  File "C:\Users\Aseman\OneDrive\Desktop\py-code\G\app\templates\base.html", line 100, in top-level template code
    {% block content %}{% endblock %}
  File "C:\Users\Aseman\OneDrive\Desktop\py-code\G\app\templates\my_lands.html", line 148, in block 'content'
    {{ land.created_at.strftime('%Y/%m/%d') }}
  File "C:\Users\Aseman\AppData\Local\Packages\PythonSoftwareFoundation.Python.3.10_qbz5n2kfra8p0\LocalCache\local-packages\Python310\site-packages\jinja2\utils.py", line 83, in from_obj
    if hasattr(obj, "jinja_pass_arg"):
jinja2.exceptions.UndefinedError: 'str object' has no attribute 'strftime'
[2025-08-21 16:13:23,230] ERROR in main: Unhandled error: 'str object' has no attribute 'strftime'
Traceback (most recent call last):
  File "C:\Users\Aseman\AppData\Local\Packages\PythonSoftwareFoundation.Python.3.10_qbz5n2kfra8p0\LocalCache\local-packages\Python310\site-packages\flask\app.py", line 1484, in full_dispatch_request
    rv = self.dispatch_request()
  File "C:\Users\Aseman\AppData\Local\Packages\PythonSoftwareFoundation.Python.3.10_qbz5n2kfra8p0\LocalCache\local-packages\Python310\site-packages\flask\app.py", line 1469, in dispatch_request
    return self.ensure_sync(self.view_functions[rule.endpoint])(**view_args)
  File "C:\Users\Aseman\OneDrive\Desktop\py-code\G\app\routes\main.py", line 469, in my_lands
    return render_template('my_lands.html',
  File "C:\Users\Aseman\AppData\Local\Packages\PythonSoftwareFoundation.Python.3.10_qbz5n2kfra8p0\LocalCache\local-packages\Python310\site-packages\flask\templating.py", line 151, in render_template
    return _render(app, template, context)
  File "C:\Users\Aseman\AppData\Local\Packages\PythonSoftwareFoundation.Python.3.10_qbz5n2kfra8p0\LocalCache\local-packages\Python310\site-packages\flask\templating.py", line 132, in _render
    rv = template.render(context)
  File "C:\Users\Aseman\AppData\Local\Packages\PythonSoftwareFoundation.Python.3.10_qbz5n2kfra8p0\LocalCache\local-packages\Python310\site-packages\jinja2\environment.py", line 1301, in render
    self.environment.handle_exception()
  File "C:\Users\Aseman\AppData\Local\Packages\PythonSoftwareFoundation.Python.3.10_qbz5n2kfra8p0\LocalCache\local-packages\Python310\site-packages\jinja2\environment.py", line 936, in handle_exception
    raise rewrite_traceback_stack(source=source)
  File "C:\Users\Aseman\OneDrive\Desktop\py-code\G\app\templates\my_lands.html", line 1, in top-level template code
    {% extends "base.html" %}
  File "C:\Users\Aseman\OneDrive\Desktop\py-code\G\app\templates\base.html", line 100, in top-level template code
    {% block content %}{% endblock %}
  File "C:\Users\Aseman\OneDrive\Desktop\py-code\G\app\templates\my_lands.html", line 148, in block 'content'
    {{ land.created_at.strftime('%Y/%m/%d') }}
  File "C:\Users\Aseman\AppData\Local\Packages\PythonSoftwareFoundation.Python.3.10_qbz5n2kfra8p0\LocalCache\local-packages\Python310\site-packages\jinja2\utils.py", line 83, in from_obj
    if hasattr(obj, "jinja_pass_arg"):
jinja2.exceptions.UndefinedError: 'str object' has no attribute 'strftime'
[2025-08-21 16:13:26,719] ERROR in main: Unhandled error: 'str object' has no attribute 'strftime'
Traceback (most recent call last):
  File "C:\Users\Aseman\AppData\Local\Packages\PythonSoftwareFoundation.Python.3.10_qbz5n2kfra8p0\LocalCache\local-packages\Python310\site-packages\flask\app.py", line 1484, in full_dispatch_request
    rv = self.dispatch_request()
  File "C:\Users\Aseman\AppData\Local\Packages\PythonSoftwareFoundation.Python.3.10_qbz5n2kfra8p0\LocalCache\local-packages\Python310\site-packages\flask\app.py", line 1469, in dispatch_request
    return self.ensure_sync(self.view_functions[rule.endpoint])(**view_args)
  File "C:\Users\Aseman\OneDrive\Desktop\py-code\G\app\routes\main.py", line 469, in my_lands
    return render_template('my_lands.html',
  File "C:\Users\Aseman\AppData\Local\Packages\PythonSoftwareFoundation.Python.3.10_qbz5n2kfra8p0\LocalCache\local-packages\Python310\site-packages\flask\templating.py", line 151, in render_template
    return _render(app, template, context)
  File "C:\Users\Aseman\AppData\Local\Packages\PythonSoftwareFoundation.Python.3.10_qbz5n2kfra8p0\LocalCache\local-packages\Python310\site-packages\flask\templating.py", line 132, in _render
    rv = template.render(context)
  File "C:\Users\Aseman\AppData\Local\Packages\PythonSoftwareFoundation.Python.3.10_qbz5n2kfra8p0\LocalCache\local-packages\Python310\site-packages\jinja2\environment.py", line 1301, in render
    self.environment.handle_exception()
  File "C:\Users\Aseman\AppData\Local\Packages\PythonSoftwareFoundation.Python.3.10_qbz5n2kfra8p0\LocalCache\local-packages\Python310\site-packages\jinja2\environment.py", line 936, in handle_exception
    raise rewrite_traceback_stack(source=source)
  File "C:\Users\Aseman\OneDrive\Desktop\py-code\G\app\templates\my_lands.html", line 1, in top-level template code
    {% extends "base.html" %}
  File "C:\Users\Aseman\OneDrive\Desktop\py-code\G\app\templates\base.html", line 100, in top-level template code
    {% block content %}{% endblock %}
  File "C:\Users\Aseman\OneDrive\Desktop\py-code\G\app\templates\my_lands.html", line 148, in block 'content'
    {{ land.created_at.strftime('%Y/%m/%d') }}
  File "C:\Users\Aseman\AppData\Local\Packages\PythonSoftwareFoundation.Python.3.10_qbz5n2kfra8p0\LocalCache\local-packages\Python310\site-packages\jinja2\utils.py", line 83, in from_obj
    if hasattr(obj, "jinja_pass_arg"):
jinja2.exceptions.UndefinedError: 'str object' has no attribute 'strftime'
[2025-08-21 16:19:42,876] ERROR in main: Unhandled error: 'str object' has no attribute 'strftime'
Traceback (most recent call last):
  File "C:\Users\Aseman\AppData\Local\Packages\PythonSoftwareFoundation.Python.3.10_qbz5n2kfra8p0\LocalCache\local-packages\Python310\site-packages\flask\app.py", line 1484, in full_dispatch_request
    rv = self.dispatch_request()
  File "C:\Users\Aseman\AppData\Local\Packages\PythonSoftwareFoundation.Python.3.10_qbz5n2kfra8p0\LocalCache\local-packages\Python310\site-packages\flask\app.py", line 1469, in dispatch_request
    return self.ensure_sync(self.view_functions[rule.endpoint])(**view_args)
  File "C:\Users\Aseman\OneDrive\Desktop\py-code\G\app\routes\main.py", line 488, in my_lands
    return render_template('my_lands.html',
  File "C:\Users\Aseman\AppData\Local\Packages\PythonSoftwareFoundation.Python.3.10_qbz5n2kfra8p0\LocalCache\local-packages\Python310\site-packages\flask\templating.py", line 151, in render_template
    return _render(app, template, context)
  File "C:\Users\Aseman\AppData\Local\Packages\PythonSoftwareFoundation.Python.3.10_qbz5n2kfra8p0\LocalCache\local-packages\Python310\site-packages\flask\templating.py", line 132, in _render
    rv = template.render(context)
  File "C:\Users\Aseman\AppData\Local\Packages\PythonSoftwareFoundation.Python.3.10_qbz5n2kfra8p0\LocalCache\local-packages\Python310\site-packages\jinja2\environment.py", line 1301, in render
    self.environment.handle_exception()
  File "C:\Users\Aseman\AppData\Local\Packages\PythonSoftwareFoundation.Python.3.10_qbz5n2kfra8p0\LocalCache\local-packages\Python310\site-packages\jinja2\environment.py", line 936, in handle_exception
    raise rewrite_traceback_stack(source=source)
  File "C:\Users\Aseman\OneDrive\Desktop\py-code\G\app\templates\my_lands.html", line 1, in top-level template code
    {% extends "base.html" %}
  File "C:\Users\Aseman\OneDrive\Desktop\py-code\G\app\templates\base.html", line 100, in top-level template code
    {% block content %}{% endblock %}
  File "C:\Users\Aseman\OneDrive\Desktop\py-code\G\app\templates\my_lands.html", line 148, in block 'content'
    {{ land.created_at.strftime('%Y/%m/%d') }}
  File "C:\Users\Aseman\AppData\Local\Packages\PythonSoftwareFoundation.Python.3.10_qbz5n2kfra8p0\LocalCache\local-packages\Python310\site-packages\jinja2\utils.py", line 83, in from_obj
    if hasattr(obj, "jinja_pass_arg"):
jinja2.exceptions.UndefinedError: 'str object' has no attribute 'strftime'
[2025-08-21 16:19:54,542] ERROR in main: Unhandled error: 'str object' has no attribute 'strftime'
Traceback (most recent call last):
  File "C:\Users\Aseman\AppData\Local\Packages\PythonSoftwareFoundation.Python.3.10_qbz5n2kfra8p0\LocalCache\local-packages\Python310\site-packages\flask\app.py", line 1484, in full_dispatch_request
    rv = self.dispatch_request()
  File "C:\Users\Aseman\AppData\Local\Packages\PythonSoftwareFoundation.Python.3.10_qbz5n2kfra8p0\LocalCache\local-packages\Python310\site-packages\flask\app.py", line 1469, in dispatch_request
    return self.ensure_sync(self.view_functions[rule.endpoint])(**view_args)
  File "C:\Users\Aseman\OneDrive\Desktop\py-code\G\app\routes\main.py", line 488, in my_lands
    return render_template('my_lands.html',
  File "C:\Users\Aseman\AppData\Local\Packages\PythonSoftwareFoundation.Python.3.10_qbz5n2kfra8p0\LocalCache\local-packages\Python310\site-packages\flask\templating.py", line 151, in render_template
    return _render(app, template, context)
  File "C:\Users\Aseman\AppData\Local\Packages\PythonSoftwareFoundation.Python.3.10_qbz5n2kfra8p0\LocalCache\local-packages\Python310\site-packages\flask\templating.py", line 132, in _render
    rv = template.render(context)
  File "C:\Users\Aseman\AppData\Local\Packages\PythonSoftwareFoundation.Python.3.10_qbz5n2kfra8p0\LocalCache\local-packages\Python310\site-packages\jinja2\environment.py", line 1301, in render
    self.environment.handle_exception()
  File "C:\Users\Aseman\AppData\Local\Packages\PythonSoftwareFoundation.Python.3.10_qbz5n2kfra8p0\LocalCache\local-packages\Python310\site-packages\jinja2\environment.py", line 936, in handle_exception
    raise rewrite_traceback_stack(source=source)
  File "C:\Users\Aseman\OneDrive\Desktop\py-code\G\app\templates\my_lands.html", line 1, in top-level template code
    {% extends "base.html" %}
  File "C:\Users\Aseman\OneDrive\Desktop\py-code\G\app\templates\base.html", line 100, in top-level template code
    {% block content %}{% endblock %}
  File "C:\Users\Aseman\OneDrive\Desktop\py-code\G\app\templates\my_lands.html", line 148, in block 'content'
    {{ land.created_at.strftime('%Y/%m/%d') }}
  File "C:\Users\Aseman\AppData\Local\Packages\PythonSoftwareFoundation.Python.3.10_qbz5n2kfra8p0\LocalCache\local-packages\Python310\site-packages\jinja2\utils.py", line 83, in from_obj
    if hasattr(obj, "jinja_pass_arg"):
jinja2.exceptions.UndefinedError: 'str object' has no attribute 'strftime'
[2025-08-21 16:21:35,980] ERROR in main: Unhandled error: 'str object' has no attribute 'strftime'
Traceback (most recent call last):
  File "C:\Users\Aseman\AppData\Local\Packages\PythonSoftwareFoundation.Python.3.10_qbz5n2kfra8p0\LocalCache\local-packages\Python310\site-packages\flask\app.py", line 1484, in full_dispatch_request
    rv = self.dispatch_request()
  File "C:\Users\Aseman\AppData\Local\Packages\PythonSoftwareFoundation.Python.3.10_qbz5n2kfra8p0\LocalCache\local-packages\Python310\site-packages\flask\app.py", line 1469, in dispatch_request
    return self.ensure_sync(self.view_functions[rule.endpoint])(**view_args)
  File "C:\Users\Aseman\OneDrive\Desktop\py-code\G\app\routes\main.py", line 488, in my_lands
    return render_template('my_lands.html',
  File "C:\Users\Aseman\AppData\Local\Packages\PythonSoftwareFoundation.Python.3.10_qbz5n2kfra8p0\LocalCache\local-packages\Python310\site-packages\flask\templating.py", line 151, in render_template
    return _render(app, template, context)
  File "C:\Users\Aseman\AppData\Local\Packages\PythonSoftwareFoundation.Python.3.10_qbz5n2kfra8p0\LocalCache\local-packages\Python310\site-packages\flask\templating.py", line 132, in _render
    rv = template.render(context)
  File "C:\Users\Aseman\AppData\Local\Packages\PythonSoftwareFoundation.Python.3.10_qbz5n2kfra8p0\LocalCache\local-packages\Python310\site-packages\jinja2\environment.py", line 1301, in render
    self.environment.handle_exception()
  File "C:\Users\Aseman\AppData\Local\Packages\PythonSoftwareFoundation.Python.3.10_qbz5n2kfra8p0\LocalCache\local-packages\Python310\site-packages\jinja2\environment.py", line 936, in handle_exception
    raise rewrite_traceback_stack(source=source)
  File "C:\Users\Aseman\OneDrive\Desktop\py-code\G\app\templates\my_lands.html", line 1, in top-level template code
    {% extends "base.html" %}
  File "C:\Users\Aseman\OneDrive\Desktop\py-code\G\app\templates\base.html", line 100, in top-level template code
    {% block content %}{% endblock %}
  File "C:\Users\Aseman\OneDrive\Desktop\py-code\G\app\templates\my_lands.html", line 148, in block 'content'
    {{ land.created_at.strftime('%Y/%m/%d') }}
  File "C:\Users\Aseman\AppData\Local\Packages\PythonSoftwareFoundation.Python.3.10_qbz5n2kfra8p0\LocalCache\local-packages\Python310\site-packages\jinja2\utils.py", line 83, in from_obj
    if hasattr(obj, "jinja_pass_arg"):
jinja2.exceptions.UndefinedError: 'str object' has no attribute 'strftime'
2025-09-02 23:02:26,604 [ERROR] app: CSRF_ERROR: The CSRF token is missing. | path=/lands/add/step3 | form={'ad_type': 'site'} | headers={'Host': '127.0.0.1:5000', 'Connection': 'keep-alive', 'Content-Length': '12', 'Cache-Control': 'max-age=0', 'Origin': 'http://127.0.0.1:5000', 'Sec-Ch-Ua-Platform': '"Windows"', 'Sec-Ch-Ua': '"Not;A=Brand";v="99", "Google Chrome";v="139", "Chromium";v="139"', 'Upgrade-Insecure-Requests': '1', 'Sec-Ch-Ua-Mobile': '?0', 'User-Agent': 'Mozilla/5.0 (Windows NT 10.0; Win64; x64) AppleWebKit/537.36 (KHTML, like Gecko) Chrome/139.0.0.0 Safari/537.36', 'Accept': 'text/html,application/xhtml+xml,application/xml;q=0.9,image/avif,image/webp,image/apng,*/*;q=0.8,application/signed-exchange;v=b3;q=0.7', 'Content-Type': 'application/x-www-form-urlencoded', 'Sec-Fetch-Site': 'same-origin', 'Sec-Fetch-Mode': 'navigate', 'Sec-Fetch-Dest': 'empty', 'Referer': 'http://127.0.0.1:5000/lands/add/step3', 'Accept-Encoding': 'gzip, deflate, br, zstd', 'Accept-Language': 'fa,en-US;q=0.9,en;q=0.8', 'Cookie': 'vinor_first_visit_done=1; session=.eJzdU8FuwyAM_ZXI52gCQ5qkv7JVEaWwVlpDBMmp6r8vwYlAVaVq220Xg96zec-WuUFnv1Q4mwD79xsU43zA1YSgPg2U8DGxHTZLFDze6yVqXSyHrCIhEyFjREt3SmoSvb5hi1RHtNZEvMHhXv7QBR4TjYogXKKyydLm-NdmjPfOv7QSFYUgKymJkC2pyaazlUdol_FoyFaWtbWYlPCvI_6fXV1669amVJsVriIiFW7lxaPU2i0ttcxkH6TCpPW8plENa1ZlzumhtQubfRiCJNGY2ZjtIWM6bTDlEyswn3OTvBxK6Abjr6o3_exp9JMpwY1Dp93JwB7aiqMAgoaz6xeMtRy5rLlgfGamYHx3OT3Hn5XcvwF0lTCP.aLBOKw.HrV7FYDvpfUCXIW33rJ5U3_7xbU; XSRF-TOKEN=IjUxNmMyZTA4OTE1NDE0NGJhOTU5Nzk3MjMxODZhNDk1YzdjM2YxM2Ui.aLdGSQ.0bip1y-JJuVeWfP7ZJuoIGU8lp0; vinor_session=.eJztmEtuhDAMhq-CvKZVnryu0o5QGsIMKi-RsGhHc_cmwCgs5gSVkXAsO7_5_C-5Q932yt6MherjDonzBwzGWnU1kMLnSjKRb1HuebIdNEStt1yEyNp4le2XWB7bnJ0qchcnUcH51lZbJdvnvcPlkSIREiEREiEREiEREiEREiEREiEREiHRvyW6pFDPZhnUaEZP5pbVpKDt0tZu-jYjVCBpppkhRUmloEJ8qVKWeZkzTotMiVLqXPOW8rBLr8am1lNjvIwRJklJGOP-Fc9mN_itww-Qy1FwZpihuoNWzlyn5ccr_d3GWL10s-umQBD9ENuSnMbKOT-MoOFjkx8Y1Yd38mRRcXYiRLLbdViUx-GHIEveEiHCJvPSaeP9caqHSogUbPcbVg4917l-y-MDjxQmNz-NobQgHPbSfJvGUCMlJVSygtAwY7Vmqbvmdf2V5PEHmsUlBA.aLdGSQ.a-NbwFc1AMmVFUNtodAosrA51WA'}
2025-09-02 23:02:31,634 [ERROR] app: CSRF_ERROR: The CSRF token is missing. | path=/lands/add/step3 | form={'ad_type': 'site'} | headers={'Host': '127.0.0.1:5000', 'Connection': 'keep-alive', 'Content-Length': '12', 'Cache-Control': 'max-age=0', 'Origin': 'http://127.0.0.1:5000', 'Sec-Ch-Ua-Platform': '"Windows"', 'Sec-Ch-Ua': '"Not;A=Brand";v="99", "Google Chrome";v="139", "Chromium";v="139"', 'Upgrade-Insecure-Requests': '1', 'Sec-Ch-Ua-Mobile': '?0', 'User-Agent': 'Mozilla/5.0 (Windows NT 10.0; Win64; x64) AppleWebKit/537.36 (KHTML, like Gecko) Chrome/139.0.0.0 Safari/537.36', 'Accept': 'text/html,application/xhtml+xml,application/xml;q=0.9,image/avif,image/webp,image/apng,*/*;q=0.8,application/signed-exchange;v=b3;q=0.7', 'Content-Type': 'application/x-www-form-urlencoded', 'Sec-Fetch-Site': 'same-origin', 'Sec-Fetch-Mode': 'navigate', 'Sec-Fetch-Dest': 'empty', 'Referer': 'http://127.0.0.1:5000/lands/add/step3', 'Accept-Encoding': 'gzip, deflate, br, zstd', 'Accept-Language': 'fa,en-US;q=0.9,en;q=0.8', 'Cookie': 'vinor_first_visit_done=1; session=.eJzdU8FuwyAM_ZXI52gCQ5qkv7JVEaWwVlpDBMmp6r8vwYlAVaVq220Xg96zec-WuUFnv1Q4mwD79xsU43zA1YSgPg2U8DGxHTZLFDze6yVqXSyHrCIhEyFjREt3SmoSvb5hi1RHtNZEvMHhXv7QBR4TjYogXKKyydLm-NdmjPfOv7QSFYUgKymJkC2pyaazlUdol_FoyFaWtbWYlPCvI_6fXV1669amVJsVriIiFW7lxaPU2i0ttcxkH6TCpPW8plENa1ZlzumhtQubfRiCJNGY2ZjtIWM6bTDlEyswn3OTvBxK6Abjr6o3_exp9JMpwY1Dp93JwB7aiqMAgoaz6xeMtRy5rLlgfGamYHx3OT3Hn5XcvwF0lTCP.aLBOKw.HrV7FYDvpfUCXIW33rJ5U3_7xbU; XSRF-TOKEN=IjUxNmMyZTA4OTE1NDE0NGJhOTU5Nzk3MjMxODZhNDk1YzdjM2YxM2Ui.aLdGTA.Iou-i4EmmMs9UseblZpit-msOxo; vinor_session=.eJztmG2OozAMhq-C_Jup8gmkV5lWKBtCB20LCFKNZqvefRMSNlF39gKrIDUEO6_92PGvPqDtr3L90Csc3x9QGPuCm15XedFQwumOKlZvK_f7Ynthtyq17ZlbSR-PEn-I1NFNSWLhXlxEBaWbW26Wysc7wPlZZqJMlIkyUSbKRJkoE2WiTJSJMlEmykSZ6P8n-pTLOIyXjYhUEp3uvUZ9koaKGIE0iR0nwBT7_EU8FQqqdZT4sgJrVUShpwzuPlHviqQiX2QIUse6pIf2H163F3_wqXjkJV2SxDPsvZVJiSQ5JcVreBIyNkXC3fzdpyRIuAiWuNk_o7t7OpfQznq5yVGP9r7MctclqHXpWzP91CMcgeNKEY0agTnDjP2Qgota1ITippJMcFUr2mPqZu4qx65VU6etjCDCkUCEUPtju3O42el0f1Sdg8Ho2wzHByhp9GVavqzSnu30qpZhNsPkCGJbGUkqxq_7MLDYJZtswKgOvUtvtkkn1q1IpR1MWvtnnt4Kxlwl8zIobftj5BWOjJWwDr9cyc5nBnPd9vGBZwmTmffGYNwgCt40f0yjsyGBEeakQdjFuK96aYfue_t3kudvu5ibVg.aLdGTA.7zX9Z_KbjgFhxg3d85p9QG47F4I'}
