[2025-08-21 16:07:08,595] ERROR in main: Unhandled error: 404 Not Found: The requested URL was not found on the server. If you entered the URL manually please check your spelling and try again.
Traceback (most recent call last):
  File "C:\Users\Aseman\AppData\Local\Packages\PythonSoftwareFoundation.Python.3.10_qbz5n2kfra8p0\LocalCache\local-packages\Python310\site-packages\flask\app.py", line 1484, in full_dispatch_request
    rv = self.dispatch_request()
  File "C:\Users\Aseman\AppData\Local\Packages\PythonSoftwareFoundation.Python.3.10_qbz5n2kfra8p0\LocalCache\local-packages\Python310\site-packages\flask\app.py", line 1469, in dispatch_request
    return self.ensure_sync(self.view_functions[rule.endpoint])(**view_args)
  File "C:\Users\Aseman\AppData\Local\Packages\PythonSoftwareFoundation.Python.3.10_qbz5n2kfra8p0\LocalCache\local-packages\Python310\site-packages\flask\app.py", line 502, in <lambda>
    view_func=lambda **kw: self_ref().send_static_file(**kw),  # type: ignore # noqa: B950
  File "C:\Users\Aseman\AppData\Local\Packages\PythonSoftwareFoundation.Python.3.10_qbz5n2kfra8p0\LocalCache\local-packages\Python310\site-packages\flask\scaffold.py", line 317, in send_static_file
    return send_from_directory(
  File "C:\Users\Aseman\AppData\Local\Packages\PythonSoftwareFoundation.Python.3.10_qbz5n2kfra8p0\LocalCache\local-packages\Python310\site-packages\flask\helpers.py", line 557, in send_from_directory
    return werkzeug.utils.send_from_directory(  # type: ignore[return-value]
  File "C:\Users\Aseman\AppData\Local\Packages\PythonSoftwareFoundation.Python.3.10_qbz5n2kfra8p0\LocalCache\local-packages\Python310\site-packages\werkzeug\utils.py", line 574, in send_from_directory
    raise NotFound()
werkzeug.exceptions.NotFound: 404 Not Found: The requested URL was not found on the server. If you entered the URL manually please check your spelling and try again.
[2025-08-21 16:07:10,938] ERROR in main: Unhandled error: 404 Not Found: The requested URL was not found on the server. If you entered the URL manually please check your spelling and try again.
Traceback (most recent call last):
  File "C:\Users\Aseman\AppData\Local\Packages\PythonSoftwareFoundation.Python.3.10_qbz5n2kfra8p0\LocalCache\local-packages\Python310\site-packages\flask\app.py", line 1484, in full_dispatch_request
    rv = self.dispatch_request()
  File "C:\Users\Aseman\AppData\Local\Packages\PythonSoftwareFoundation.Python.3.10_qbz5n2kfra8p0\LocalCache\local-packages\Python310\site-packages\flask\app.py", line 1458, in dispatch_request
    self.raise_routing_exception(req)
  File "C:\Users\Aseman\AppData\Local\Packages\PythonSoftwareFoundation.Python.3.10_qbz5n2kfra8p0\LocalCache\local-packages\Python310\site-packages\flask\app.py", line 1440, in raise_routing_exception
    raise request.routing_exception  # type: ignore
  File "C:\Users\Aseman\AppData\Local\Packages\PythonSoftwareFoundation.Python.3.10_qbz5n2kfra8p0\LocalCache\local-packages\Python310\site-packages\flask\ctx.py", line 353, in match_request
    result = self.url_adapter.match(return_rule=True)  # type: ignore
  File "C:\Users\Aseman\AppData\Local\Packages\PythonSoftwareFoundation.Python.3.10_qbz5n2kfra8p0\LocalCache\local-packages\Python310\site-packages\werkzeug\routing\map.py", line 655, in match
    raise NotFound() from None
werkzeug.exceptions.NotFound: 404 Not Found: The requested URL was not found on the server. If you entered the URL manually please check your spelling and try again.
[2025-08-21 16:07:14,330] ERROR in main: Unhandled error: 404 Not Found: The requested URL was not found on the server. If you entered the URL manually please check your spelling and try again.
Traceback (most recent call last):
  File "C:\Users\Aseman\AppData\Local\Packages\PythonSoftwareFoundation.Python.3.10_qbz5n2kfra8p0\LocalCache\local-packages\Python310\site-packages\flask\app.py", line 1484, in full_dispatch_request
    rv = self.dispatch_request()
  File "C:\Users\Aseman\AppData\Local\Packages\PythonSoftwareFoundation.Python.3.10_qbz5n2kfra8p0\LocalCache\local-packages\Python310\site-packages\flask\app.py", line 1458, in dispatch_request
    self.raise_routing_exception(req)
  File "C:\Users\Aseman\AppData\Local\Packages\PythonSoftwareFoundation.Python.3.10_qbz5n2kfra8p0\LocalCache\local-packages\Python310\site-packages\flask\app.py", line 1440, in raise_routing_exception
    raise request.routing_exception  # type: ignore
  File "C:\Users\Aseman\AppData\Local\Packages\PythonSoftwareFoundation.Python.3.10_qbz5n2kfra8p0\LocalCache\local-packages\Python310\site-packages\flask\ctx.py", line 353, in match_request
    result = self.url_adapter.match(return_rule=True)  # type: ignore
  File "C:\Users\Aseman\AppData\Local\Packages\PythonSoftwareFoundation.Python.3.10_qbz5n2kfra8p0\LocalCache\local-packages\Python310\site-packages\werkzeug\routing\map.py", line 655, in match
    raise NotFound() from None
werkzeug.exceptions.NotFound: 404 Not Found: The requested URL was not found on the server. If you entered the URL manually please check your spelling and try again.
[2025-08-21 16:07:27,135] ERROR in main: Unhandled error: 404 Not Found: The requested URL was not found on the server. If you entered the URL manually please check your spelling and try again.
Traceback (most recent call last):
  File "C:\Users\Aseman\AppData\Local\Packages\PythonSoftwareFoundation.Python.3.10_qbz5n2kfra8p0\LocalCache\local-packages\Python310\site-packages\flask\app.py", line 1484, in full_dispatch_request
    rv = self.dispatch_request()
  File "C:\Users\Aseman\AppData\Local\Packages\PythonSoftwareFoundation.Python.3.10_qbz5n2kfra8p0\LocalCache\local-packages\Python310\site-packages\flask\app.py", line 1469, in dispatch_request
    return self.ensure_sync(self.view_functions[rule.endpoint])(**view_args)
  File "C:\Users\Aseman\AppData\Local\Packages\PythonSoftwareFoundation.Python.3.10_qbz5n2kfra8p0\LocalCache\local-packages\Python310\site-packages\flask\app.py", line 502, in <lambda>
    view_func=lambda **kw: self_ref().send_static_file(**kw),  # type: ignore # noqa: B950
  File "C:\Users\Aseman\AppData\Local\Packages\PythonSoftwareFoundation.Python.3.10_qbz5n2kfra8p0\LocalCache\local-packages\Python310\site-packages\flask\scaffold.py", line 317, in send_static_file
    return send_from_directory(
  File "C:\Users\Aseman\AppData\Local\Packages\PythonSoftwareFoundation.Python.3.10_qbz5n2kfra8p0\LocalCache\local-packages\Python310\site-packages\flask\helpers.py", line 557, in send_from_directory
    return werkzeug.utils.send_from_directory(  # type: ignore[return-value]
  File "C:\Users\Aseman\AppData\Local\Packages\PythonSoftwareFoundation.Python.3.10_qbz5n2kfra8p0\LocalCache\local-packages\Python310\site-packages\werkzeug\utils.py", line 574, in send_from_directory
    raise NotFound()
werkzeug.exceptions.NotFound: 404 Not Found: The requested URL was not found on the server. If you entered the URL manually please check your spelling and try again.
[2025-08-21 16:08:01,672] ERROR in main: Unhandled error: 404 Not Found: The requested URL was not found on the server. If you entered the URL manually please check your spelling and try again.
Traceback (most recent call last):
  File "C:\Users\Aseman\AppData\Local\Packages\PythonSoftwareFoundation.Python.3.10_qbz5n2kfra8p0\LocalCache\local-packages\Python310\site-packages\flask\app.py", line 1484, in full_dispatch_request
    rv = self.dispatch_request()
  File "C:\Users\Aseman\AppData\Local\Packages\PythonSoftwareFoundation.Python.3.10_qbz5n2kfra8p0\LocalCache\local-packages\Python310\site-packages\flask\app.py", line 1469, in dispatch_request
    return self.ensure_sync(self.view_functions[rule.endpoint])(**view_args)
  File "C:\Users\Aseman\AppData\Local\Packages\PythonSoftwareFoundation.Python.3.10_qbz5n2kfra8p0\LocalCache\local-packages\Python310\site-packages\flask\app.py", line 502, in <lambda>
    view_func=lambda **kw: self_ref().send_static_file(**kw),  # type: ignore # noqa: B950
  File "C:\Users\Aseman\AppData\Local\Packages\PythonSoftwareFoundation.Python.3.10_qbz5n2kfra8p0\LocalCache\local-packages\Python310\site-packages\flask\scaffold.py", line 317, in send_static_file
    return send_from_directory(
  File "C:\Users\Aseman\AppData\Local\Packages\PythonSoftwareFoundation.Python.3.10_qbz5n2kfra8p0\LocalCache\local-packages\Python310\site-packages\flask\helpers.py", line 557, in send_from_directory
    return werkzeug.utils.send_from_directory(  # type: ignore[return-value]
  File "C:\Users\Aseman\AppData\Local\Packages\PythonSoftwareFoundation.Python.3.10_qbz5n2kfra8p0\LocalCache\local-packages\Python310\site-packages\werkzeug\utils.py", line 574, in send_from_directory
    raise NotFound()
werkzeug.exceptions.NotFound: 404 Not Found: The requested URL was not found on the server. If you entered the URL manually please check your spelling and try again.
[2025-08-21 16:08:03,482] ERROR in main: Unhandled error: 'str object' has no attribute 'strftime'
Traceback (most recent call last):
  File "C:\Users\Aseman\AppData\Local\Packages\PythonSoftwareFoundation.Python.3.10_qbz5n2kfra8p0\LocalCache\local-packages\Python310\site-packages\flask\app.py", line 1484, in full_dispatch_request
    rv = self.dispatch_request()
  File "C:\Users\Aseman\AppData\Local\Packages\PythonSoftwareFoundation.Python.3.10_qbz5n2kfra8p0\LocalCache\local-packages\Python310\site-packages\flask\app.py", line 1469, in dispatch_request
    return self.ensure_sync(self.view_functions[rule.endpoint])(**view_args)
  File "C:\Users\Aseman\OneDrive\Desktop\py-code\G\app\routes\main.py", line 469, in my_lands
    return render_template('my_lands.html',
  File "C:\Users\Aseman\AppData\Local\Packages\PythonSoftwareFoundation.Python.3.10_qbz5n2kfra8p0\LocalCache\local-packages\Python310\site-packages\flask\templating.py", line 151, in render_template
    return _render(app, template, context)
  File "C:\Users\Aseman\AppData\Local\Packages\PythonSoftwareFoundation.Python.3.10_qbz5n2kfra8p0\LocalCache\local-packages\Python310\site-packages\flask\templating.py", line 132, in _render
    rv = template.render(context)
  File "C:\Users\Aseman\AppData\Local\Packages\PythonSoftwareFoundation.Python.3.10_qbz5n2kfra8p0\LocalCache\local-packages\Python310\site-packages\jinja2\environment.py", line 1301, in render
    self.environment.handle_exception()
  File "C:\Users\Aseman\AppData\Local\Packages\PythonSoftwareFoundation.Python.3.10_qbz5n2kfra8p0\LocalCache\local-packages\Python310\site-packages\jinja2\environment.py", line 936, in handle_exception
    raise rewrite_traceback_stack(source=source)
  File "C:\Users\Aseman\OneDrive\Desktop\py-code\G\app\templates\my_lands.html", line 1, in top-level template code
    {% extends "base.html" %}
  File "C:\Users\Aseman\OneDrive\Desktop\py-code\G\app\templates\base.html", line 100, in top-level template code
    {% block content %}{% endblock %}
  File "C:\Users\Aseman\OneDrive\Desktop\py-code\G\app\templates\my_lands.html", line 148, in block 'content'
    {{ land.created_at.strftime('%Y/%m/%d') }}
  File "C:\Users\Aseman\AppData\Local\Packages\PythonSoftwareFoundation.Python.3.10_qbz5n2kfra8p0\LocalCache\local-packages\Python310\site-packages\jinja2\utils.py", line 83, in from_obj
    if hasattr(obj, "jinja_pass_arg"):
jinja2.exceptions.UndefinedError: 'str object' has no attribute 'strftime'
[2025-08-21 16:08:03,640] ERROR in main: Unhandled error: 404 Not Found: The requested URL was not found on the server. If you entered the URL manually please check your spelling and try again.
Traceback (most recent call last):
  File "C:\Users\Aseman\AppData\Local\Packages\PythonSoftwareFoundation.Python.3.10_qbz5n2kfra8p0\LocalCache\local-packages\Python310\site-packages\flask\app.py", line 1484, in full_dispatch_request
    rv = self.dispatch_request()
  File "C:\Users\Aseman\AppData\Local\Packages\PythonSoftwareFoundation.Python.3.10_qbz5n2kfra8p0\LocalCache\local-packages\Python310\site-packages\flask\app.py", line 1458, in dispatch_request
    self.raise_routing_exception(req)
  File "C:\Users\Aseman\AppData\Local\Packages\PythonSoftwareFoundation.Python.3.10_qbz5n2kfra8p0\LocalCache\local-packages\Python310\site-packages\flask\app.py", line 1440, in raise_routing_exception
    raise request.routing_exception  # type: ignore
  File "C:\Users\Aseman\AppData\Local\Packages\PythonSoftwareFoundation.Python.3.10_qbz5n2kfra8p0\LocalCache\local-packages\Python310\site-packages\flask\ctx.py", line 353, in match_request
    result = self.url_adapter.match(return_rule=True)  # type: ignore
  File "C:\Users\Aseman\AppData\Local\Packages\PythonSoftwareFoundation.Python.3.10_qbz5n2kfra8p0\LocalCache\local-packages\Python310\site-packages\werkzeug\routing\map.py", line 655, in match
    raise NotFound() from None
werkzeug.exceptions.NotFound: 404 Not Found: The requested URL was not found on the server. If you entered the URL manually please check your spelling and try again.
[2025-08-21 16:13:20,131] ERROR in main: Unhandled error: 'str object' has no attribute 'strftime'
Traceback (most recent call last):
  File "C:\Users\Aseman\AppData\Local\Packages\PythonSoftwareFoundation.Python.3.10_qbz5n2kfra8p0\LocalCache\local-packages\Python310\site-packages\flask\app.py", line 1484, in full_dispatch_request
    rv = self.dispatch_request()
  File "C:\Users\Aseman\AppData\Local\Packages\PythonSoftwareFoundation.Python.3.10_qbz5n2kfra8p0\LocalCache\local-packages\Python310\site-packages\flask\app.py", line 1469, in dispatch_request
    return self.ensure_sync(self.view_functions[rule.endpoint])(**view_args)
  File "C:\Users\Aseman\OneDrive\Desktop\py-code\G\app\routes\main.py", line 469, in my_lands
    return render_template('my_lands.html',
  File "C:\Users\Aseman\AppData\Local\Packages\PythonSoftwareFoundation.Python.3.10_qbz5n2kfra8p0\LocalCache\local-packages\Python310\site-packages\flask\templating.py", line 151, in render_template
    return _render(app, template, context)
  File "C:\Users\Aseman\AppData\Local\Packages\PythonSoftwareFoundation.Python.3.10_qbz5n2kfra8p0\LocalCache\local-packages\Python310\site-packages\flask\templating.py", line 132, in _render
    rv = template.render(context)
  File "C:\Users\Aseman\AppData\Local\Packages\PythonSoftwareFoundation.Python.3.10_qbz5n2kfra8p0\LocalCache\local-packages\Python310\site-packages\jinja2\environment.py", line 1301, in render
    self.environment.handle_exception()
  File "C:\Users\Aseman\AppData\Local\Packages\PythonSoftwareFoundation.Python.3.10_qbz5n2kfra8p0\LocalCache\local-packages\Python310\site-packages\jinja2\environment.py", line 936, in handle_exception
    raise rewrite_traceback_stack(source=source)
  File "C:\Users\Aseman\OneDrive\Desktop\py-code\G\app\templates\my_lands.html", line 1, in top-level template code
    {% extends "base.html" %}
  File "C:\Users\Aseman\OneDrive\Desktop\py-code\G\app\templates\base.html", line 100, in top-level template code
    {% block content %}{% endblock %}
  File "C:\Users\Aseman\OneDrive\Desktop\py-code\G\app\templates\my_lands.html", line 148, in block 'content'
    {{ land.created_at.strftime('%Y/%m/%d') }}
  File "C:\Users\Aseman\AppData\Local\Packages\PythonSoftwareFoundation.Python.3.10_qbz5n2kfra8p0\LocalCache\local-packages\Python310\site-packages\jinja2\utils.py", line 83, in from_obj
    if hasattr(obj, "jinja_pass_arg"):
jinja2.exceptions.UndefinedError: 'str object' has no attribute 'strftime'
[2025-08-21 16:13:23,230] ERROR in main: Unhandled error: 'str object' has no attribute 'strftime'
Traceback (most recent call last):
  File "C:\Users\Aseman\AppData\Local\Packages\PythonSoftwareFoundation.Python.3.10_qbz5n2kfra8p0\LocalCache\local-packages\Python310\site-packages\flask\app.py", line 1484, in full_dispatch_request
    rv = self.dispatch_request()
  File "C:\Users\Aseman\AppData\Local\Packages\PythonSoftwareFoundation.Python.3.10_qbz5n2kfra8p0\LocalCache\local-packages\Python310\site-packages\flask\app.py", line 1469, in dispatch_request
    return self.ensure_sync(self.view_functions[rule.endpoint])(**view_args)
  File "C:\Users\Aseman\OneDrive\Desktop\py-code\G\app\routes\main.py", line 469, in my_lands
    return render_template('my_lands.html',
  File "C:\Users\Aseman\AppData\Local\Packages\PythonSoftwareFoundation.Python.3.10_qbz5n2kfra8p0\LocalCache\local-packages\Python310\site-packages\flask\templating.py", line 151, in render_template
    return _render(app, template, context)
  File "C:\Users\Aseman\AppData\Local\Packages\PythonSoftwareFoundation.Python.3.10_qbz5n2kfra8p0\LocalCache\local-packages\Python310\site-packages\flask\templating.py", line 132, in _render
    rv = template.render(context)
  File "C:\Users\Aseman\AppData\Local\Packages\PythonSoftwareFoundation.Python.3.10_qbz5n2kfra8p0\LocalCache\local-packages\Python310\site-packages\jinja2\environment.py", line 1301, in render
    self.environment.handle_exception()
  File "C:\Users\Aseman\AppData\Local\Packages\PythonSoftwareFoundation.Python.3.10_qbz5n2kfra8p0\LocalCache\local-packages\Python310\site-packages\jinja2\environment.py", line 936, in handle_exception
    raise rewrite_traceback_stack(source=source)
  File "C:\Users\Aseman\OneDrive\Desktop\py-code\G\app\templates\my_lands.html", line 1, in top-level template code
    {% extends "base.html" %}
  File "C:\Users\Aseman\OneDrive\Desktop\py-code\G\app\templates\base.html", line 100, in top-level template code
    {% block content %}{% endblock %}
  File "C:\Users\Aseman\OneDrive\Desktop\py-code\G\app\templates\my_lands.html", line 148, in block 'content'
    {{ land.created_at.strftime('%Y/%m/%d') }}
  File "C:\Users\Aseman\AppData\Local\Packages\PythonSoftwareFoundation.Python.3.10_qbz5n2kfra8p0\LocalCache\local-packages\Python310\site-packages\jinja2\utils.py", line 83, in from_obj
    if hasattr(obj, "jinja_pass_arg"):
jinja2.exceptions.UndefinedError: 'str object' has no attribute 'strftime'
[2025-08-21 16:13:26,719] ERROR in main: Unhandled error: 'str object' has no attribute 'strftime'
Traceback (most recent call last):
  File "C:\Users\Aseman\AppData\Local\Packages\PythonSoftwareFoundation.Python.3.10_qbz5n2kfra8p0\LocalCache\local-packages\Python310\site-packages\flask\app.py", line 1484, in full_dispatch_request
    rv = self.dispatch_request()
  File "C:\Users\Aseman\AppData\Local\Packages\PythonSoftwareFoundation.Python.3.10_qbz5n2kfra8p0\LocalCache\local-packages\Python310\site-packages\flask\app.py", line 1469, in dispatch_request
    return self.ensure_sync(self.view_functions[rule.endpoint])(**view_args)
  File "C:\Users\Aseman\OneDrive\Desktop\py-code\G\app\routes\main.py", line 469, in my_lands
    return render_template('my_lands.html',
  File "C:\Users\Aseman\AppData\Local\Packages\PythonSoftwareFoundation.Python.3.10_qbz5n2kfra8p0\LocalCache\local-packages\Python310\site-packages\flask\templating.py", line 151, in render_template
    return _render(app, template, context)
  File "C:\Users\Aseman\AppData\Local\Packages\PythonSoftwareFoundation.Python.3.10_qbz5n2kfra8p0\LocalCache\local-packages\Python310\site-packages\flask\templating.py", line 132, in _render
    rv = template.render(context)
  File "C:\Users\Aseman\AppData\Local\Packages\PythonSoftwareFoundation.Python.3.10_qbz5n2kfra8p0\LocalCache\local-packages\Python310\site-packages\jinja2\environment.py", line 1301, in render
    self.environment.handle_exception()
  File "C:\Users\Aseman\AppData\Local\Packages\PythonSoftwareFoundation.Python.3.10_qbz5n2kfra8p0\LocalCache\local-packages\Python310\site-packages\jinja2\environment.py", line 936, in handle_exception
    raise rewrite_traceback_stack(source=source)
  File "C:\Users\Aseman\OneDrive\Desktop\py-code\G\app\templates\my_lands.html", line 1, in top-level template code
    {% extends "base.html" %}
  File "C:\Users\Aseman\OneDrive\Desktop\py-code\G\app\templates\base.html", line 100, in top-level template code
    {% block content %}{% endblock %}
  File "C:\Users\Aseman\OneDrive\Desktop\py-code\G\app\templates\my_lands.html", line 148, in block 'content'
    {{ land.created_at.strftime('%Y/%m/%d') }}
  File "C:\Users\Aseman\AppData\Local\Packages\PythonSoftwareFoundation.Python.3.10_qbz5n2kfra8p0\LocalCache\local-packages\Python310\site-packages\jinja2\utils.py", line 83, in from_obj
    if hasattr(obj, "jinja_pass_arg"):
jinja2.exceptions.UndefinedError: 'str object' has no attribute 'strftime'
[2025-08-21 16:19:42,876] ERROR in main: Unhandled error: 'str object' has no attribute 'strftime'
Traceback (most recent call last):
  File "C:\Users\Aseman\AppData\Local\Packages\PythonSoftwareFoundation.Python.3.10_qbz5n2kfra8p0\LocalCache\local-packages\Python310\site-packages\flask\app.py", line 1484, in full_dispatch_request
    rv = self.dispatch_request()
  File "C:\Users\Aseman\AppData\Local\Packages\PythonSoftwareFoundation.Python.3.10_qbz5n2kfra8p0\LocalCache\local-packages\Python310\site-packages\flask\app.py", line 1469, in dispatch_request
    return self.ensure_sync(self.view_functions[rule.endpoint])(**view_args)
  File "C:\Users\Aseman\OneDrive\Desktop\py-code\G\app\routes\main.py", line 488, in my_lands
    return render_template('my_lands.html',
  File "C:\Users\Aseman\AppData\Local\Packages\PythonSoftwareFoundation.Python.3.10_qbz5n2kfra8p0\LocalCache\local-packages\Python310\site-packages\flask\templating.py", line 151, in render_template
    return _render(app, template, context)
  File "C:\Users\Aseman\AppData\Local\Packages\PythonSoftwareFoundation.Python.3.10_qbz5n2kfra8p0\LocalCache\local-packages\Python310\site-packages\flask\templating.py", line 132, in _render
    rv = template.render(context)
  File "C:\Users\Aseman\AppData\Local\Packages\PythonSoftwareFoundation.Python.3.10_qbz5n2kfra8p0\LocalCache\local-packages\Python310\site-packages\jinja2\environment.py", line 1301, in render
    self.environment.handle_exception()
  File "C:\Users\Aseman\AppData\Local\Packages\PythonSoftwareFoundation.Python.3.10_qbz5n2kfra8p0\LocalCache\local-packages\Python310\site-packages\jinja2\environment.py", line 936, in handle_exception
    raise rewrite_traceback_stack(source=source)
  File "C:\Users\Aseman\OneDrive\Desktop\py-code\G\app\templates\my_lands.html", line 1, in top-level template code
    {% extends "base.html" %}
  File "C:\Users\Aseman\OneDrive\Desktop\py-code\G\app\templates\base.html", line 100, in top-level template code
    {% block content %}{% endblock %}
  File "C:\Users\Aseman\OneDrive\Desktop\py-code\G\app\templates\my_lands.html", line 148, in block 'content'
    {{ land.created_at.strftime('%Y/%m/%d') }}
  File "C:\Users\Aseman\AppData\Local\Packages\PythonSoftwareFoundation.Python.3.10_qbz5n2kfra8p0\LocalCache\local-packages\Python310\site-packages\jinja2\utils.py", line 83, in from_obj
    if hasattr(obj, "jinja_pass_arg"):
jinja2.exceptions.UndefinedError: 'str object' has no attribute 'strftime'
[2025-08-21 16:19:54,542] ERROR in main: Unhandled error: 'str object' has no attribute 'strftime'
Traceback (most recent call last):
  File "C:\Users\Aseman\AppData\Local\Packages\PythonSoftwareFoundation.Python.3.10_qbz5n2kfra8p0\LocalCache\local-packages\Python310\site-packages\flask\app.py", line 1484, in full_dispatch_request
    rv = self.dispatch_request()
  File "C:\Users\Aseman\AppData\Local\Packages\PythonSoftwareFoundation.Python.3.10_qbz5n2kfra8p0\LocalCache\local-packages\Python310\site-packages\flask\app.py", line 1469, in dispatch_request
    return self.ensure_sync(self.view_functions[rule.endpoint])(**view_args)
  File "C:\Users\Aseman\OneDrive\Desktop\py-code\G\app\routes\main.py", line 488, in my_lands
    return render_template('my_lands.html',
  File "C:\Users\Aseman\AppData\Local\Packages\PythonSoftwareFoundation.Python.3.10_qbz5n2kfra8p0\LocalCache\local-packages\Python310\site-packages\flask\templating.py", line 151, in render_template
    return _render(app, template, context)
  File "C:\Users\Aseman\AppData\Local\Packages\PythonSoftwareFoundation.Python.3.10_qbz5n2kfra8p0\LocalCache\local-packages\Python310\site-packages\flask\templating.py", line 132, in _render
    rv = template.render(context)
  File "C:\Users\Aseman\AppData\Local\Packages\PythonSoftwareFoundation.Python.3.10_qbz5n2kfra8p0\LocalCache\local-packages\Python310\site-packages\jinja2\environment.py", line 1301, in render
    self.environment.handle_exception()
  File "C:\Users\Aseman\AppData\Local\Packages\PythonSoftwareFoundation.Python.3.10_qbz5n2kfra8p0\LocalCache\local-packages\Python310\site-packages\jinja2\environment.py", line 936, in handle_exception
    raise rewrite_traceback_stack(source=source)
  File "C:\Users\Aseman\OneDrive\Desktop\py-code\G\app\templates\my_lands.html", line 1, in top-level template code
    {% extends "base.html" %}
  File "C:\Users\Aseman\OneDrive\Desktop\py-code\G\app\templates\base.html", line 100, in top-level template code
    {% block content %}{% endblock %}
  File "C:\Users\Aseman\OneDrive\Desktop\py-code\G\app\templates\my_lands.html", line 148, in block 'content'
    {{ land.created_at.strftime('%Y/%m/%d') }}
  File "C:\Users\Aseman\AppData\Local\Packages\PythonSoftwareFoundation.Python.3.10_qbz5n2kfra8p0\LocalCache\local-packages\Python310\site-packages\jinja2\utils.py", line 83, in from_obj
    if hasattr(obj, "jinja_pass_arg"):
jinja2.exceptions.UndefinedError: 'str object' has no attribute 'strftime'
[2025-08-21 16:21:35,980] ERROR in main: Unhandled error: 'str object' has no attribute 'strftime'
Traceback (most recent call last):
  File "C:\Users\Aseman\AppData\Local\Packages\PythonSoftwareFoundation.Python.3.10_qbz5n2kfra8p0\LocalCache\local-packages\Python310\site-packages\flask\app.py", line 1484, in full_dispatch_request
    rv = self.dispatch_request()
  File "C:\Users\Aseman\AppData\Local\Packages\PythonSoftwareFoundation.Python.3.10_qbz5n2kfra8p0\LocalCache\local-packages\Python310\site-packages\flask\app.py", line 1469, in dispatch_request
    return self.ensure_sync(self.view_functions[rule.endpoint])(**view_args)
  File "C:\Users\Aseman\OneDrive\Desktop\py-code\G\app\routes\main.py", line 488, in my_lands
    return render_template('my_lands.html',
  File "C:\Users\Aseman\AppData\Local\Packages\PythonSoftwareFoundation.Python.3.10_qbz5n2kfra8p0\LocalCache\local-packages\Python310\site-packages\flask\templating.py", line 151, in render_template
    return _render(app, template, context)
  File "C:\Users\Aseman\AppData\Local\Packages\PythonSoftwareFoundation.Python.3.10_qbz5n2kfra8p0\LocalCache\local-packages\Python310\site-packages\flask\templating.py", line 132, in _render
    rv = template.render(context)
  File "C:\Users\Aseman\AppData\Local\Packages\PythonSoftwareFoundation.Python.3.10_qbz5n2kfra8p0\LocalCache\local-packages\Python310\site-packages\jinja2\environment.py", line 1301, in render
    self.environment.handle_exception()
  File "C:\Users\Aseman\AppData\Local\Packages\PythonSoftwareFoundation.Python.3.10_qbz5n2kfra8p0\LocalCache\local-packages\Python310\site-packages\jinja2\environment.py", line 936, in handle_exception
    raise rewrite_traceback_stack(source=source)
  File "C:\Users\Aseman\OneDrive\Desktop\py-code\G\app\templates\my_lands.html", line 1, in top-level template code
    {% extends "base.html" %}
  File "C:\Users\Aseman\OneDrive\Desktop\py-code\G\app\templates\base.html", line 100, in top-level template code
    {% block content %}{% endblock %}
  File "C:\Users\Aseman\OneDrive\Desktop\py-code\G\app\templates\my_lands.html", line 148, in block 'content'
    {{ land.created_at.strftime('%Y/%m/%d') }}
  File "C:\Users\Aseman\AppData\Local\Packages\PythonSoftwareFoundation.Python.3.10_qbz5n2kfra8p0\LocalCache\local-packages\Python310\site-packages\jinja2\utils.py", line 83, in from_obj
    if hasattr(obj, "jinja_pass_arg"):
jinja2.exceptions.UndefinedError: 'str object' has no attribute 'strftime'
